Seed:  3719875988211458818
Testing 1 Robots
Process Solving:
Traceback (most recent call last):
  File "/home/salewsky/.conda/envs/Clingo2/lib/python3.9/multiprocessing/process.py", line 315, in _bootstrap
    self.run()
  File "/home/salewsky/.conda/envs/Clingo2/lib/python3.9/multiprocessing/process.py", line 108, in run
    self._target(*self._args, **self._kwargs)
  File "/home/salewsky/MAPF-Project/random_benchmark_solver.py", line 103, in solving
    ctl.ground([("base", [])])
  File "/home/salewsky/.conda/envs/Clingo2/lib/python3.9/site-packages/clingo/control.py", line 338, in ground
    _handle_error(_lib.clingo_control_ground(
  File "/home/salewsky/.conda/envs/Clingo2/lib/python3.9/site-packages/clingo/_internal.py", line 64, in _handle_error
    raise MemoryError(msg)
MemoryError: bad_alloc
